<?xml version="1.0"?>
<robot xmlns:xacro="http://www.ros.org/wiki/xacro">
    <link name="chassis_link">
        <visual>
            <origin xyz="0.0 0.0 0.0375"/>
            <geometry>
                <cylinder radius="0.170" length="0.075"/>
            </geometry>
            <material name="gray">
                <color rgba="0.5 0.5 0.5 1"/>
            </material>
        </visual>
    </link>

    <link name="left_wheel">
        <visual>
            <origin xyz="0.0 0.0 0.0"/>
            <geometry>
                <cylinder radius="0.0375" length="0.016"/>
                <material>
                    <color rgba="1 0.0 0.0 1"/>
                </material>
            </geometry>
        </visual>
    </link>

    <link name="right_wheel">
        <visual>
            <origin xyz="0.0 0.0 0.0"/>
            <geometry>
                <cylinder radius="0.0375" length="0.016"/>
                <material>
                    <color rgba="1 0.0 0.0 1"/>
                </material>
            </geometry>
        </visual>
    </link>

    <link name="caster_wheel">
        <visual>
            <origin xyz="0.0 0.0 0.0"/>
            <geometry>
                <sphere radius="0.047"/>
            </geometry>
            <material name="white">
                <color rgba="1.0 1.0 1.0 1.0"/>
            </material>
        </visual>
    </link>

    <joint name="caster_joint" type="continuous">
        <origin xyz="0.129 0.0 0.0" rpy="0.0 0.0 0.0"/>

        <parent link="chassis_link"/>
        <child link="caster_wheel"/>
    
        <axis xyz="0.0 1.0 0.0"/>
    </joint>

    <joint name="left_wheel_joint" type="continuous">
        <origin xyz="0.0 0.110 0.0" rpy="${pi/2} 0.0 0.0"/>
        <parent link="chassis_link"/>
        <child link="left_wheel"/>
        <axis xyz="0.0 0.0 -1.0"/>
    </joint>

    <joint name="right_wheel_joint" type="continuous">
        <origin xyz="0.0 -0.110 0.0" rpy="${pi/2} 0.0 0.0"/>
        <parent link="chassis_link"/>
        <child link="right_wheel"/>
        <axis xyz="0.0 0.0 -1.0"/>
    </joint>
</robot>