<?xml version="1.0" ?>
<!-- =================================================================================== -->
<!-- |    This document was autogenerated by xacro from robot_base.urdf.xacro          | -->
<!-- |    EDITING THIS FILE BY HAND IS NOT RECOMMENDED                                 | -->
<!-- =================================================================================== -->
<robot name="roomba_891">
  <link name="world"/>
  <material name="red">
    <color rgba="1.0 0.0 0.0 1.0"/>
  </material>
  <material name="green">
    <color rgba="0.0 1.0 0.0 1.0"/>
  </material>
  <material name="blue">
    <color rgba="0.0 0.0 1.0 1.0"/>
  </material>
  <material name="yellow">
    <color rgba="1.0 1.0 0.0 1.0"/>
  </material>
  <material name="black">
    <color rgba="0.0 0.0 0.0 1.0"/>
  </material>
  <material name="white">
    <color rgba="1.0 1.0 1.0 1.0"/>
  </material>
  <material name="grey">
    <color rgba="0.5 0.5 0.5 1.0"/>
  </material>
  <material name="dark_grey">
    <color rgba="0.25 0.25 0.25 1.0"/>
  </material>
  <material name="light_grey">
    <color rgba="0.75 0.75 0.75 1.0"/>
  </material>
  <material name="orange">
    <color rgba="1.0 0.5 0.0 1.0"/>
  </material>
  <!-- source en.wikipedia.org/wiki/List_of_moments_of_inertia-->
  <gazebo reference="chassis_link">
    <material>Gazebo/Grey</material>
  </gazebo>
  <gazebo reference="left_wheel">
    <material>Gazebo/Red</material>
  </gazebo>
  <gazebo reference="right_wheel">
    <material>Gazebo/Red</material>
  </gazebo>
  <gazebo reference="caster_wheel">
    <material>Gazebo/Red</material>
  </gazebo>
  <gazebo>
    <plugin filename="gz-sim-joint-state-publisher-system" name="gz::sim::systems::JointStatePublisher">
      <topic>/joint_states</topic>
      <joint>caster_joint</joint>
      <joint>left_wheel_joint</joint>
      <joint>right_wheel_joint</joint>
    </plugin>
  </gazebo>
  <link name="chassis_link">
    <visual>
      <origin xyz="0.0 0.0 0.0375"/>
      <geometry>
        <cylinder length="0.075" radius="0.17"/>
      </geometry>
      <material name="grey"/>
    </visual>
    <collision>
      <origin xyz="0.0 0.0 0.0375"/>
      <geometry>
        <cylinder length="0.075" radius="0.17"/>
      </geometry>
    </collision>
    <inertial>
      <mass value="2.95"/>
      <inertia ixx="0.022696562500000007" ixy="0" ixz="0" iyy="0.022696562500000007" iyz="0" izz="0.042627500000000006"/>
    </inertial>
  </link>
  <link name="left_wheel">
    <visual>
      <origin xyz="0.0 0.0 0.0"/>
      <geometry>
        <cylinder length="0.016" radius="0.0375"/>
      </geometry>
      <material name="red"/>
    </visual>
    <collision>
      <geometry>
        <cylinder length="0.016" radius="0.0375"/>
      </geometry>
    </collision>
    <inertial>
      <mass value="0.226796"/>
      <inertia ixx="8.457128341666667e-05" ixy="0" ixz="0" iyy="8.457128341666667e-05" iyz="0" izz="0.00015946593749999999"/>
    </inertial>
  </link>
  <link name="right_wheel">
    <visual>
      <origin xyz="0.0 0.0 0.0"/>
      <geometry>
        <cylinder length="0.016" radius="0.0375"/>
      </geometry>
      <material name="red"/>
    </visual>
    <collision>
      <geometry>
        <cylinder length="0.016" radius="0.0375"/>
      </geometry>
    </collision>
    <inertial>
      <mass value="0.226796"/>
      <inertia ixx="8.457128341666667e-05" ixy="0" ixz="0" iyy="8.457128341666667e-05" iyz="0" izz="0.00015946593749999999"/>
    </inertial>
  </link>
  <link name="caster_wheel">
    <visual>
      <origin xyz="0.0 0.0 0.0"/>
      <geometry>
        <sphere radius="0.047"/>
      </geometry>
      <material name="red"/>
    </visual>
    <collision>
      <geometry>
        <sphere radius="0.047"/>
      </geometry>
    </collision>
    <inertial>
      <mass value="0.05"/>
      <inertia ixx="7.363333333333334e-05" ixy="0" ixz="0" iyy="7.363333333333334e-05" iyz="0" izz="7.363333333333334e-05"/>
    </inertial>
  </link>
  <joint name="caster_joint" type="continuous">
    <origin rpy="0.0 0.0 0.0" xyz="0.129 0.0 0.0"/>
    <parent link="chassis_link"/>
    <child link="caster_wheel"/>
    <axis xyz="0.0 1.0 0.0"/>
  </joint>
  <joint name="left_wheel_joint" type="continuous">
    <origin rpy="1.5707963267948966 0.0 0.0" xyz="0.0 0.11 0.0"/>
    <parent link="chassis_link"/>
    <child link="left_wheel"/>
    <axis xyz="0.0 0.0 -1.0"/>
  </joint>
  <joint name="right_wheel_joint" type="continuous">
    <origin rpy="1.5707963267948966 0.0 0.0" xyz="0.0 -0.11 0.0"/>
    <parent link="chassis_link"/>
    <child link="right_wheel"/>
    <axis xyz="0.0 0.0 -1.0"/>
  </joint>
  <joint name="base_joint" type="fixed">
    <origin rpy="0.0 0.0 0.0" xyz="0.0 0.0 0.016"/>
    <parent link="world"/>
    <child link="chassis_link"/>
  </joint>
</robot>
